<?xml version="1.0" ?>
<!-- =================================================================================== -->
<!-- |    This document was autogenerated by xacro from /opt/ros/noetic/share/franka_description/robots/panda/panda.urdf.xacro | -->
<!-- |    EDITING THIS FILE BY HAND IS NOT RECOMMENDED                                 | -->
<!-- =================================================================================== -->
<robot name="panda">
  <!-- sub-link defining detailed meshes for collision with environment -->
  
 <link name="world">
  </link>
  <joint name="world" type="fixed">
    <parent link="world"/>
    <child link="panda_link0"/>
  </joint>

  <link
    name="panda_link0">
    <inertial>
      <origin
        xyz="-0.00031896 -0.00029673 0.042463"
        rpy="0 0 0" />
      <mass
        value="1.6185" />
      <inertia
        ixx="0.0030836"
        ixy="1.5354E-05"
        ixz="-1.9315E-05"
        iyy="0.0030825"
        iyz="-1.7918E-05"
        izz="0.0045209" />
    </inertial>
    <visual>
      <origin
        xyz="0 0 0"
        rpy="0 0 0" />
      <geometry>
        <mesh
          filename="package://franka_description/robots/fr5v6/visual/base_link.DAE" />
      </geometry>
      <material
        name="">
        <color
          rgba="0.89804 0.91765 0.92941 1" />
      </material>
    </visual>
    <collision>
      <origin
        xyz="0 0 0"
        rpy="0 0 0" />
      <geometry>
        <mesh
          filename="package://franka_description/robots/fr5v6/collision/base_link.STL" />
      </geometry>
    </collision>
  </link>
  <link
    name="panda_link1">
    <inertial>
      <origin
        xyz="5.0029E-07 -0.0040922 0.14629"
        rpy="0 0 0" />
      <mass
        value="4.3771" />
      <inertia
        ixx="0.010731"
        ixy="-8.0587E-09"
        ixz="-3.6773E-08"
        iyy="0.010408"
        iyz="0.00012853"
        izz="0.0081793" />
    </inertial>
    <visual>
      <origin
        xyz="0 0 0"
        rpy="0 0 0" />
      <geometry>
        <mesh
          filename="package://franka_description/robots/fr5v6/visual/j1_Link.DAE" />
      </geometry>
      <material
        name="">
        <color
          rgba="0.89804 0.91765 0.92941 1" />
      </material>
    </visual>
    <collision>
      <origin
        xyz="0 0 0"
        rpy="0 0 0" />
      <geometry>
        <mesh
          filename="package://franka_description/robots/fr5v6/collision/j1_Link.STL" />
      </geometry>
    </collision>
  </link>
  <joint
    name="panda_joint1"
    type="revolute">
    <origin
      xyz="0 0 0"
      rpy="0 0 0" />
    <parent
      link="panda_link0" />
    <child
      link="panda_link1" />
    <axis
      xyz="0 0 1" />
    <limit
      lower="-3.0543"
      upper="3.0543"
      effort="150"
      velocity="3.15" />
    <calibration
      rising="0"
      falling="0" />
    <dynamics
      damping="0"
      friction="0" />
    <safety_controller
      soft_lower_limit="-3.0543"
      soft_upper_limit="3.0543"
      k_position="15"
      k_velocity="10" />
  </joint>
  <link
    name="panda_link2">
    <inertial>
      <origin
        xyz="-0.2125 -5.7643E-09 0.1346"
        rpy="0 0 0" />
      <mass
        value="14.458" />
      <inertia
        ixx="0.028392"
        ixy="-1.337E-07"
        ixz="-3.9895E-09"
        iyy="0.4559"
        iyz="4.214E-08"
        izz="0.44974" />
    </inertial>
    <visual>
      <origin
        xyz="0 0 0"
        rpy="0 0 0" />
      <geometry>
        <mesh
          filename="package://franka_description/robots/fr5v6/visual/j2_Link.DAE" />
      </geometry>
      <material
        name="">
        <color
          rgba="0.89804 0.91765 0.92941 1" />
      </material>
    </visual>
    <collision>
      <origin
        xyz="0 0 0"
        rpy="0 0 0" />
      <geometry>
        <mesh
          filename="package://franka_description/robots/fr5v6/collision/j2_Link.STL" />
      </geometry>
    </collision>
  </link>
  <joint
    name="panda_joint2"
    type="revolute">
    <origin
      xyz="0 0 0.152"
      rpy="1.5708 0 0" />
    <parent
      link="panda_link1" />
    <child
      link="panda_link2" />
    <axis
      xyz="0 0 1" />
    <limit
      lower="-4.6251"
      upper="1.4835"
      effort="150"
      velocity="3.15" />
    <calibration
      rising="0"
      falling="0" />
    <dynamics
      damping="0"
      friction="0" />
    <safety_controller
      soft_lower_limit="-4.6251"
      soft_upper_limit="1.4835"
      k_position="15"
      k_velocity="10" />
  </joint>
  <link
    name="panda_link3">
    <inertial>
      <origin
        xyz="-0.18793 -8.4503E-07 0.0066357"
        rpy="0 0 0" />
      <mass
        value="7.6737" />
      <inertia
        ixx="0.0085096"
        ixy="2.1613E-06"
        ixz="-0.0068678"
        iyy="0.16971"
        iyz="3.7086E-08"
        izz="0.16854" />
    </inertial>
    <visual>
      <origin
        xyz="0 0 0"
        rpy="0 0 0" />
      <geometry>
        <mesh
          filename="package://franka_description/robots/fr5v6/visual/j3_Link.DAE" />
      </geometry>
      <material
        name="">
        <color
          rgba="0.89804 0.91765 0.92941 1" />
      </material>
    </visual>
    <collision>
      <origin
        xyz="0 0 0"
        rpy="0 0 0" />
      <geometry>
        <mesh
          filename="package://franka_description/robots/fr5v6/collision/j3_Link.STL" />
      </geometry>
    </collision>
  </link>
  <joint
    name="panda_join3"
    type="revolute">
    <origin
      xyz="-0.425 0 0"
      rpy="0 0 0" />
    <parent
      link="panda_link2" />
    <child
      link="panda_link3" />
    <axis
      xyz="0 0 1" />
    <limit
      lower="-2.8274"
      upper="2.8274"
      effort="150"
      velocity="3.15" />
    <calibration
      rising="0"
      falling="0" />
    <dynamics
      damping="0"
      friction="0" />
    <safety_controller
      soft_lower_limit="-2.8274"
      soft_upper_limit="2.8274"
      k_position="15"
      k_velocity="10" />
  </joint>
  <link
    name="panda_link4">
    <inertial>
      <origin
        xyz="4.98E-07 -0.003754 0.097155"
        rpy="0 0 0" />
      <mass
        value="1.6266" />
      <inertia
        ixx="0.00216"
        ixy="4.888E-09"
        ixz="3.1528E-08"
        iyy="0.0015455"
        iyz="3.7678E-05"
        izz="0.0019902" />
    </inertial>
    <visual>
      <origin
        xyz="0 0 0"
        rpy="0 0 0" />
      <geometry>
        <mesh
          filename="package://franka_description/robots/fr5v6/visual/j4_Link.DAE" />
      </geometry>
      <material
        name="">
        <color
          rgba="0.89804 0.91765 0.92941 1" />
      </material>
    </visual>
    <collision>
      <origin
        xyz="0 0 0"
        rpy="0 0 0" />
      <geometry>
        <mesh
          filename="package://franka_description/robots/fr5v6/collision/j4_Link.STL" />
      </geometry>
    </collision>
  </link>
  <joint
    name="panda_join4"
    type="revolute">
    <origin
      xyz="-0.39501 0 0"
      rpy="0 0 0" />
    <parent
      link="panda_link3" />
    <child
      link="panda_link4" />
    <axis
      xyz="0 0 1" />
    <limit
      lower="-4.6251"
      upper="1.4835"
      effort="28"
      velocity="3.2" />
    <calibration
      rising="0"
      falling="0" />
    <dynamics
      damping="0"
      friction="0" />
    <safety_controller
      soft_lower_limit="-4.6251"
      soft_upper_limit="1.4835"
      k_position="15"
      k_velocity="10" />
  </joint>
  <link
    name="panda_link5">
    <inertial>
      <origin
        xyz="-4.5588E-07 0.0038617 0.098257"
        rpy="0 0 0" />
      <mass
        value="1.5812" />
      <inertia
        ixx="0.0020612"
        ixy="8.7064E-09"
        ixz="-3.4742E-08"
        iyy="0.0014477"
        iyz="-2.8534E-05"
        izz="0.0019573" />
    </inertial>
    <visual>
      <origin
        xyz="0 0 0"
        rpy="0 0 0" />
      <geometry>
        <mesh
          filename="package://franka_description/robots/fr5v6/visual/j5_Link.DAE" />
      </geometry>
      <material
        name="">
        <color
          rgba="0.89804 0.91765 0.92941 1" />
      </material>
    </visual>
    <collision>
      <origins
        xyz="0 0 0"
        rpy="0 0 0" />
      <geometry>
        <mesh
          filename="package://franka_description/robots/fr5v6/collision/j5_Link.STL" />
      </geometry>
    </collision>
  </link>
  <joint
    name="panda_join5"
    type="revolute">
    <origin
      xyz="0 0 0.1021"
      rpy="1.5708 0 0" />
    <parent
      link="panda_link4" />
    <child
      link="panda_link5" />
    <axis
      xyz="0 0 1" />
    <limit
      lower="-3.0543"
      upper="3.0543"
      effort="28"
      velocity="3.2" />
    <calibration
      rising="0"
      falling="0" />
    <dynamics
      damping="0"
      friction="0" />
    <safety_controller
      soft_lower_limit="-3.0543"
      soft_upper_limit="3.0543"
      k_position="15"
      k_velocity="10" />
  </joint>
  <link
    name="panda_link6">
    <inertial>
      <origin
        xyz="7.7496E-05 1.7751E-05 0.076122"
        rpy="0 0 0" />
      <mass
        value="0.52542" />
      <inertia
        ixx="0.00027721"
        ixy="-1.8677E-09"
        ixz="-1.188E-07"
        iyy="0.00027839"
        iyz="2.2607E-07"
        izz="0.00041605" />
    </inertial>
    <visual>
      <origin
        xyz="0 0 0"
        rpy="0 0 0" />
      <geometry>
        <mesh
          filename="package://franka_description/robots/fr5v6/visual/j6_Link.DAE" />
      </geometry>
      <material
        name="">
        <color
          rgba="0.89804 0.91765 0.92941 1" />
      </material>
    </visual>
    <collision>
      <origin
        xyz="0 0 0"
        rpy="0 0 0" />
      <geometry>
        <mesh
          filename="package://franka_description/robots/fr5v6/collision/j6_Link.STL" />
      </geometry>
    </collision>
  </link>
  <joint
    name="panda_join6"
    type="revolute">
    <origin
      xyz="0 0 0.102"
      rpy="-1.5708 0 0" />
    <parent
      link="panda_link5" />
    <child
      link="panda_link6" />
    <axis
      xyz="0 0 1" />
    <limit
      lower="-3.0543"
      upper="3.0543"
      effort="28"
      velocity="3.2" />
    <calibration
      rising="0"
      falling="0" />
    <dynamics
      damping="0"
      friction="0" />
    <safety_controller
      soft_lower_limit="-3.0543"
      soft_upper_limit="3.0543"
      k_position="15"
      k_velocity="10" />
  </joint>
  

  <joint name="k_ee" type="fixed">
    <parent link="panda_hand"/>
    <child link="k_ee_link"/>
    <origin rpy="0 0 0" xyz="0 0 0.103399"/>
  </joint>
  <link name="k_ee_link">
  </link>


  <!-- Panda hand -->
  <joint name="panda_hand_joint" type="fixed">
    <parent link="panda_link6"/>
    <child link="panda_hand"/>
    <origin rpy="0 0 -0.785398163397" xyz="0 0 0.107"/>
  </joint>


  <link
    name="panda_hand">
    <inertial>
      <origin
        xyz="0.000590732710131745 -0.00212482055829597 0.0390711121564613"
        rpy="0 0 0" />
      <mass
        value="0.410076712822003" />
      <inertia
        ixx="0.000490743093860451"
        ixy="8.88694180287399E-06"
        ixz="-4.40788336869861E-07"
        iyy="0.000921185312665057"
        iyz="3.47120316959879E-05"
        izz="0.00085013675383108" />
    </inertial>
    <visual>
      <origin
        xyz="0 0 0"
        rpy="0 0 0" />
      <geometry>
        <mesh
          filename="package://franka_description/robots/Gripper/meshes/panda_hand.dae" />
      </geometry>
      <material
        name="">
        <color
          rgba="0.749019607843137 0.749019607843137 0.749019607843137 1" />
      </material>
    </visual>
    <collision>
      <origin
        xyz="0 0 0"
        rpy="0 0 0" />
      <geometry>
        <mesh
          filename="package://franka_description/robots/Gripper/meshes/panda_hand.stl" />
      </geometry>
    </collision>
  </link>
  <link
    name="Left_Gripper">
    <inertial>
      <origin
        xyz="-0.14078 0.018679 0.052776"
        rpy="0 0 0" />
      <mass
        value="0.11401" />
      <inertia
        ixx="7.9791E-05"
        ixy="-1.4328E-07"
        ixz="-6.9009E-06"
        iyy="9.604E-05"
        iyz="1.6264E-08"
        izz="3.962E-05" />
    </inertial>
    <visual>
      <origin
        xyz="0 0 0"
        rpy="0 0 0" />
      <geometry>
        <mesh
          filename="package://franka_description/robots/Gripper/meshes/Left_Gripper.dae" />
      </geometry>
      <material
        name="">
        <color
          rgba="0.79216 0.81961 0.93333 1" />
      </material>
    </visual>
    <collision>
      <origin
        xyz="0 0 0"
        rpy="0 0 0" />
      <geometry>
        <mesh
          filename="package://franka_description/robots/Gripper/meshes/Left_Gripper.stl" />
      </geometry>
    </collision>
  </link>
  <joint
    name="LG"
    type="prismatic">
    <origin
      xyz="0.071084 -0.02241 0.0801"
      rpy="0 0 0" />
    <parent
      link="panda_hand" />
    <child
      link="Left_Gripper" />
    <axis
      xyz="1 0 0" />
    <limit
      lower="0"
      upper="0.055"
      effort="10"
      velocity="0.1" />
  </joint>
  <link
    name="Right_Gripper">
    <inertial>
      <origin
        xyz="-0.14059 0.0092217 0.053953"
        rpy="0 0 0" />
      <mass
        value="0.11017" />
      <inertia
        ixx="7.7997E-05"
        ixy="-1.4178E-07"
        ixz="-6.9009E-06"
        iyy="9.5588E-05"
        iyz="9.38E-09"
        izz="3.7415E-05" />
    </inertial>
    <visual>
      <origin
        xyz="0 0 0"
        rpy="0 0 0" />
      <geometry>
        <mesh
          filename="package://franka_description/robots/Gripper/meshes/Right_Gripper.dae" />
      </geometry>
      <material
        name="">
        <color
          rgba="0.79216 0.81961 0.93333 1" />
      </material>
    </visual>
    <collision>
      <origin
        xyz="0 0 0"
        rpy="0 0 0" />
      <geometry>
        <mesh
          filename="package://franka_description/robots/Gripper/meshes/Right_Gripper.stl" />
      </geometry>
    </collision>
  </link>
  <joint
    name="RG"
    type="prismatic">
    <origin
      xyz="-0.071084 0.01159 0.0801"
      rpy="0 0 -3.1416" />
    <parent
      link="panda_hand" />
    <child
      link="Right_Gripper" />
    <axis
      xyz="1 0 0" />
    <limit
      lower="0"
      upper="0.055"
      effort="10"
      velocity="0.1" />
  </joint>

</robot>
