<?xml version="1.0" ?>
<!-- =================================================================================== -->
<!-- |    This document was autogenerated by xacro from /opt/ros/noetic/share/franka_description/robots/panda/panda.urdf.xacro | -->
<!-- |    EDITING THIS FILE BY HAND IS NOT RECOMMENDED                                 | -->
<!-- =================================================================================== -->
<robot name="panda">
  <!-- sub-link defining detailed meshes for collision with environment -->
  <link
    name="panda_link0">
    <inertial>
      <origin
        xyz="0.000608631599856789 0.000101410841223995 0.0500536423028974"
        rpy="0 0 0" />
      <mass
        value="0.725732279372378" />
      <inertia
        ixx="0.00116526259312761"
        ixy="3.86984764047093E-06"
        ixz="3.61598634195121E-05"
        iyy="0.00114387939249178"
        iyz="-1.69159565748085E-06"
        izz="0.000799620765266388" />
    </inertial>
    <visual>
      <origin
        xyz="0 0 0"
        rpy="0 0 0" />
      <geometry>
        <mesh
          filename="package://franka_description/robots/meshes_gen/base_link.dae" />
      </geometry>
      <material
        name="">
        <color
          rgba="1 1 1 1" />
      </material>
    </visual>
    <collision>
      <origin
        xyz="0 0 0"
        rpy="0 0 0" />
      <geometry>
        <mesh
          filename="package://franka_description/robots/meshes_gen/base_link.STL" />
      </geometry>
    </collision>
  </link>
  <link
    name="panda_link1">
    <inertial>
      <origin rpy="0 0 0" xyz="-0.041018 -0.00014 0.049974"/>
      <mass value="0.629769"/>
      <inertia ixx="0.00315" ixy="8.2904e-07" ixz="0.00015" iyy="0.00388" iyz="8.2299e-06" izz="0.004285"/>
    </inertial>
    <visual>
      <origin
        xyz="0 0 0"
        rpy="0 0 0" />
      <origin
        xyz="0 0 0"
        rpy="0 0 0" />
      <geometry>
        <mesh
          filename="package://franka_description/robots/meshes_gen/Link1.dae" />
      </geometry>
      <material
        name="">
        <color
          rgba="1 1 1 1" />
      </material>
    </visual>
    <collision>
      <origin
        xyz="0 0 0"
        rpy="0 0 0" />
      <origin
        xyz="0 0 0"
        rpy="0 0 0" />
      <geometry>
        <mesh
          filename="package://franka_description/robots/meshes_gen/Link1.STL" />
      </geometry>
    </collision>
  </link>
  <joint
    name="panda_joint1"
    type="revolute">
    <origin
      xyz="0 0 0.218"
      rpy="0 0 0" />
    <parent
      link="panda_link0" />
    <child
      link="panda_link1" />
    <axis
      xyz="0 0 1" />
    <limit
      lower="-3.0014"
      upper="3.0014"
      effort="25"
      velocity="3.141" />
  </joint>
  <link
    name="panda_link2">
    <inertial>
      <origin
        xyz="-7.09647952406739E-07 -0.0576246216953338 -3.88440270542586E-05"
        rpy="0 0 0" />
      <mass
        value="0.551907023014854" />
      <inertia
        ixx="0.00142140348660833"
        ixy="-1.11203318362369E-08"
        ixz="1.36371990293752E-08"
        iyy="0.00052571427239726"
        iyz="1.30499471891358E-06"
        izz="0.00127234961251408" />
    </inertial>
    <visual>
      <origin
        xyz="0 0 0"
        rpy="0 0 0" />
      <origin
        xyz="0 0 0"
        rpy="0 0 0" />
      <geometry>
        <mesh
          filename="package://franka_description/robots/meshes_gen/Link2.dae" />
      </geometry>
      <material
        name="">
        <color
          rgba="1 1 1 1" />
      </material>
    </visual>
    <collision>
      <origin
        xyz="0 0 0"
        rpy="0 0 0" />
      <origin
        xyz="0 0 0"
        rpy="0 0 0" />
      <geometry>
        <mesh
          filename="package://franka_description/robots/meshes_gen/Link2.STL" />
      </geometry>
    </collision>
  </link>
  <joint
    name="panda_joint2"
    type="revolute">
    <origin
      xyz="0 0 0"
      rpy="-1.5708 0 0" />
    <parent
      link="panda_link1" />
    <child
      link="panda_link2" />
    <axis
      xyz="0 0 1" />
    <limit
      lower="-1.8323"
      upper="1.8323"
      effort="25"
      velocity="3.141" />
  </joint>
  <link
    name="panda_link3">
    <inertial>
      <origin rpy="0 0 0" xyz="-0.003141 -0.02872  0.003495"/>
      <mass value="0.646926"/>
      <inertia ixx="0.007962" ixy="-0.003925" ixz="0.010254" iyy="0.02811" iyz="0.000704" izz="0.025995"/>
    </inertial>
    <visual>
      <origin
        xyz="0 0 0"
        rpy="0 0 0" />
      <geometry>
        <mesh filename="package://franka_description/meshes/visual/link3.dae"/>
      </geometry>
    </visual>
    <collision>
      <origin
        xyz="0 0 0"
        rpy="0 0 0" />
      <geometry>
        <mesh filename="package://franka_description/meshes/collision/link3.stl"/>
      </geometry>
    </collision>
    <inertial>
      <origin rpy="0 0 0" xyz="2.7518e-02 3.9252e-02 -6.6502e-02"/>
      <mass value="3.228604"/>
      <inertia ixx="0.037242" ixy="-0.004761" ixz="-0.011396" iyy="0.036155" iyz="-0.012805" izz="0.01083"/>
    </inertial>
    <visual>
      <origin
        xyz="0 0 0"
        rpy="0 0 0" />
      <geometry>
        <mesh filename="package://franka_description/meshes/visual/link4.dae"/>
      </geometry>
    </visual>
    <collision>
      <origin
        xyz="0 0 0"
        rpy="0 0 0" />
      <geometry>
        <mesh filename="package://franka_description/meshes/collision/link4.stl"/>
      </geometry>
    </collision>
    <inertial>
      <origin rpy="0 0 0" xyz="-5.317e-02 1.04419e-01 2.7454e-02"/>
      <mass value="3.587895"/>
      <inertia ixx="0.025853" ixy="0.007796" ixz="-0.001332" iyy="0.019552" iyz="0.008641" izz="0.028323"/>
    </inertial>
    <visual>
      <origin
        xyz="0 0 0"
        rpy="0 0 0" />
      <geometry>
        <mesh filename="package://franka_description/meshes/visual/link5.dae"/>
      </geometry>
    </visual>
    <collision>
      <origin
        xyz="0 0 0"
        rpy="0 0 0" />
      <geometry>
        <mesh filename="package://franka_description/meshes/collision/link5.stl"/>
      </geometry>
    </collision>
    <inertial>
      <origin rpy="0 0 0" xyz="-1.1953e-02 4.1065e-02 -3.8437e-02"/>
      <mass value="1.225946"/>
      <inertia ixx="0.035549" ixy="-0.002117" ixz="-0.004037" iyy="0.029474" iyz="0.000229" izz="0.008627"/>
    </inertial>
    <visual>
      <origin
        xyz="0 0 0"
        rpy="0 0 0" />
      <geometry>
        <mesh filename="package://franka_description/meshes/visual/link6.dae"/>
      </geometry>
    </visual>
    <collision>
      <geometry>
        <mesh filename="package://franka_description/meshes/collision/link6.stl"/>
      </geometry>
    </collision>
    <inertial>
      <origin rpy="0 0 0" xyz="6.0149e-02 -1.4117e-02 -1.0517e-02"/>
      <mass value="1.666555"/>
      <inertia ixx="0.001964" ixy="0.000109" ixz="-0.001158" iyy="0.004354" iyz="0.000341" izz="0.005433"/>
    </inertial>
    <visual>
      <origin
        xyz="0 0 0"
        rpy="0 0 0" />
      <geometry>
        <mesh filename="package://franka_description/meshes/visual/link7.dae"/>
      </geometry>
    </visual>
    <collision>
      <origin
        xyz="0 0 0"
        rpy="0 0 0" />
      <geometry>
        <mesh filename="package://franka_description/meshes/collision/link7.stl"/>
      </geometry>
    </collision>
  </link>
  <!-- sub-link defining coarse geometries of real robot's internal self-collision -->
  <link name="panda_link7_sc">
  </link>
  <!-- fixed joint between both sub-links -->
  <joint name="panda_link7_sc_joint" type="fixed">
    <origin rpy="0 0 0.7853981633974483"/>
    <parent link="panda_link7"/>
    <child link="panda_link7_sc"/>
  </joint>
  <joint name="panda_joint7" type="revolute">
    <origin rpy="1.5707963267948966 0 0" xyz="0.088 0 0"/>
    <parent link="panda_link6"/>
    <child link="panda_link7"/>
    <axis xyz="0 0 1"/>
    <limit effort="12.0" lower="-2.8973" upper="2.8973" velocity="2.61"/>
    <safety_controller k_position="100.0" k_velocity="40.0" soft_lower_limit="-2.8973" soft_upper_limit="2.8973"/>
    <dynamics D="1" K="7000" damping="0.003" friction="0.0" mu_coulomb="0" mu_viscous="16"/>
  </joint>
  <link name="k_ee_link">
  </link>


  <!-- Panda hand -->
  <joint name="panda_hand_joint" type="fixed">
    <parent link="panda_link6"/>
    <child link="panda_hand"/>
    <origin rpy="0 0 0" xyz="0 0 0"/>
  </joint>
  <link name="panda_hand">
    <visual>
      <origin
        xyz="0 0 0"
        rpy="0 0 0" />
      <geometry>
        <mesh
          filename="package://franka_description/robots/Gripper/meshes/panda_hand.dae" />
      </geometry>
      <material
        name="">
        <color
          rgba="0.749019607843137 0.749019607843137 0.749019607843137 1" />
      </material>
    </visual>
    <collision>
      <origin
        xyz="0 0 0"
        rpy="0 0 0" />
      <geometry>
        <mesh
          filename="package://franka_description/robots/Gripper/meshes/panda_hand.stl" />
      </geometry>
    </collision>
  </link>
  <link name="panda_leftfinger">
    <visual>
      <origin
        xyz="0 0 0"
        rpy="0 0 0" />
      <geometry>
        <mesh
          filename="package://franka_description/robots/Gripper/meshes/Left_Gripper.dae" />
      </geometry>
      <material
        name="">
        <color
          rgba="0.79216 0.81961 0.93333 1" />
      </material>
    </visual>
    <collision>
      <origin rpy="0 0 0" xyz="0 18.5e-3 11e-3"/>
      <geometry>
        <box size="22e-3 15e-3 20e-3"/>
      </geometry>
    </collision>
    <!-- cartriage sledge -->
    <collision>
      <origin rpy="0 0 0" xyz="0 6.8e-3 2.2e-3"/>
      <geometry>
        <box size="22e-3 8.8e-3 3.8e-3"/>
      </geometry>
    </collision>
    <!-- diagonal finger -->
    <collision>
      <origin rpy="0.5235987755982988 0 0" xyz="0 15.9e-3 28.35e-3"/>
      <geometry>
        <box size="17.5e-3 7e-3 23.5e-3"/>
      </geometry>
    </collision>
    <!-- rubber tip with which to grasp -->
    <collision>
      <origin rpy="0 0 0" xyz="0 7.58e-3 45.25e-3"/>
      <geometry>
        <box size="17.5e-3 15.2e-3 18.5e-3"/>
      </geometry>
    </collision>
  </link>
  <link name="panda_rightfinger">
    <visual>
      <origin
        xyz="0 0 0"
        rpy="0 0 0" />
      <geometry>
        <mesh
          filename="package://franka_description/robots/Gripper/meshes/Right_Gripper.dae" />
      </geometry>
      <material
        name="">
        <color
          rgba="0.79216 0.81961 0.93333 1" />
      </material>
    </visual>
    <collision>
      <origin rpy="0 0 0" xyz="0 -18.5e-3 11e-3"/>
      <geometry>
        <box size="22e-3 15e-3 20e-3"/>
      </geometry>
    </collision>
    <!-- cartriage sledge -->
    <collision>
      <origin rpy="0 0 0" xyz="0 -6.8e-3 2.2e-3"/>
      <geometry>
        <box size="22e-3 8.8e-3 3.8e-3"/>
      </geometry>
    </collision>
    <!-- diagonal finger -->
    <collision>
      <origin rpy="-0.5235987755982988 0 0" xyz="0 -15.9e-3 28.35e-3"/>
      <geometry>
        <box size="17.5e-3 7e-3 23.5e-3"/>
      </geometry>
    </collision>
    <!-- rubber tip with which to grasp -->
    <collision>
      <origin rpy="0 0 0" xyz="0 -7.58e-3 45.25e-3"/>
      <geometry>
        <box size="17.5e-3 15.2e-3 18.5e-3"/>
      </geometry>
    </collision>
  </link>
  <joint name="panda_finger_joint1" type="prismatic">
    <parent link="panda_hand"/>
    <child link="panda_leftfinger"/>
    <origin rpy="0 0 0" xyz="0 0 0.0584"/>
    <axis xyz="0 1 0"/>
    <limit effort="100" lower="0.0" upper="0.04" velocity="0.2"/>
    <dynamics damping="0.3"/>
  </joint>
  <joint name="panda_finger_joint2" type="prismatic">
    <parent link="panda_hand"/>
    <child link="panda_rightfinger"/>
    <origin rpy="0 0 0" xyz="0 0 0.0584"/>
    <axis xyz="0 -1 0"/>
    <limit effort="100" lower="0.0" upper="0.04" velocity="0.2"/>
    <mimic joint="panda_finger_joint1"/>
    <dynamics damping="0.3"/>
  </joint>
  <joint name="k_ee" type="fixed">
    <parent link="panda_hand"/>
    <child link="k_ee_link"/>
    <origin rpy="0 0 0" xyz="0 0 0.103399"/>
  </joint>
  <link name="k_ee_link">
  </link>
</robot>
