<?xml version="1.0" ?>
<!-- =================================================================================== -->
<!-- |    This document was autogenerated by xacro from /opt/ros/noetic/share/franka_description/robots/panda/panda.urdf.xacro | -->
<!-- |    EDITING THIS FILE BY HAND IS NOT RECOMMENDED                                 | -->
<!-- =================================================================================== -->
<robot name="panda">
  <!-- sub-link defining detailed meshes for collision with environment -->
  <link
    name="panda_link0">
    <inertial>
      <origin
        xyz="0.000608631599856789 0.000101410841223995 0.0500536423028974"
        rpy="0 0 0" />
      <mass
        value="0.725732279372378" />
      <inertia
        ixx="0.00116526259312761"
        ixy="3.86984764047093E-06"
        ixz="3.61598634195121E-05"
        iyy="0.00114387939249178"
        iyz="-1.69159565748085E-06"
        izz="0.000799620765266388" />
    </inertial>
    <visual>
      <origin
        xyz="0 0 0"
        rpy="0 0 0" />
      <geometry>
        <mesh
          filename="package://franka_description/robots/meshes_gen/base_link.dae" />
      </geometry>
      <material
        name="">
        <color
          rgba="1 1 1 1" />
      </material>
    </visual>
    <collision>
      <origin
        xyz="0 0 0"
        rpy="0 0 0" />
      <geometry>
        <mesh
          filename="package://franka_description/robots/meshes_gen/base_link.STL" />
      </geometry>
    </collision>
  </link>
  <link
    name="panda_link1">
    <inertial>
      <origin
        xyz="3.54241616240111E-07 -6.0407327765511E-05 -0.0474562076947793"
        rpy="0 0 0" />
      <mass
        value="0.511231576042974" />
      <inertia
        ixx="0.000959440501675413"
        ixy="-1.90967914521862E-09"
        ixz="-7.95751539476377E-09"
        iyy="0.00102039305288465"
        iyz="1.46570590325122E-06"
        izz="0.000388714616194907" />
    </inertial>
    <visual>
      <origin
        xyz="0 0 0"
        rpy="0 0 0" />
      <geometry>
        <mesh
          filename="package://franka_description/robots/meshes_gen/Link1.dae" />
      </geometry>
      <material
        name="">
        <color
          rgba="1 1 1 1" />
      </material>
    </visual>
    <collision>
      <origin
        xyz="0 0 0"
        rpy="0 0 0" />
      <geometry>
        <mesh
          filename="package://franka_description/robots/meshes_gen/Link1.STL" />
      </geometry>
    </collision>
  </link>
  <joint
    name="panda_joint1"
    type="revolute">
    <origin
      xyz="0 0 0.218"
      rpy="0 0 0" />
    <parent
      link="panda_link0" />
    <child
      link="panda_link1" />
    <axis
      xyz="0 0 1" />
    <limit
      lower="-3.0014"
      upper="3.0014"
      effort="25"
      velocity="3.141" />
  </joint>
  <link
    name="panda_link2">
    <inertial>
      <origin
        xyz="-7.09647952406739E-07 -0.0576246216953338 -3.88440270542586E-05"
        rpy="0 0 0" />
      <mass
        value="0.551907023014854" />
      <inertia
        ixx="0.00142140348660833"
        ixy="-1.11203318362369E-08"
        ixz="1.36371990293752E-08"
        iyy="0.00052571427239726"
        iyz="1.30499471891358E-06"
        izz="0.00127234961251408" />
    </inertial>
    <visual>
      <origin
        xyz="0 0 0"
        rpy="0 0 0" />
      <geometry>
        <mesh
          filename="package://franka_description/robots/meshes_gen/Link2.dae" />
      </geometry>
      <material
        name="">
        <color
          rgba="1 1 1 1" />
      </material>
    </visual>
    <collision>
      <origin
        xyz="0 0 0"
        rpy="0 0 0" />
      <geometry>
        <mesh
          filename="package://franka_description/robots/meshes_gen/Link2.STL" />
      </geometry>
    </collision>
  </link>
  <joint
    name="panda_joint2"
    type="revolute">
    <origin
      xyz="0 0 0"
      rpy="-1.5708 0 0" />
    <parent
      link="panda_link1" />
    <child
      link="panda_link2" />
    <axis
      xyz="0 0 1" />
    <limit
      lower="-1.8323"
      upper="1.8323"
      effort="25"
      velocity="3.141" />
  </joint>
  <link
    name="panda_link3">
    <inertial>
      <origin
        xyz="0.00897441376214204 2.62633968732461E-05 -0.07382847021305"
        rpy="0 0 0" />
      <mass
        value="0.774130450031718" />
      <inertia
        ixx="0.00242102073961794"
        ixy="-6.22596416744426E-07"
        ixz="-0.000489521447339786"
        iyy="0.00248694314969312"
        iyz="-1.48542895560703E-06"
        izz="0.000900997189719803" />
    </inertial>
    <visual>
      <origin
        xyz="0 0 0"
        rpy="0 0 0" />
      <geometry>
        <mesh
          filename="package://franka_description/robots/meshes_gen/Link3.dae" />
      </geometry>
      <material
        name="">
        <color
          rgba="1 1 1 1" />
      </material>
    </visual>
    <collision>
      <origin
        xyz="0 0 0"
        rpy="0 0 0" />
      <geometry>
        <mesh
          filename="package://franka_description/robots/meshes_gen/Link3.STL" />
      </geometry>
    </collision>
  </link>
  <joint
    name="panda_joint3"
    type="revolute">
    <origin
      xyz="0 -0.28 0"
      rpy="1.5708 0 0" />
    <parent
      link="panda_link2" />
    <child
      link="panda_link3" />
    <axis
      xyz="0 0 1" />
    <limit
      lower="-3.0014"
      upper="3.0014"
      effort="25"
      velocity="3.141" />
  </joint>
  <link
    name="panda_link4">
    <inertial>
      <origin
        xyz="-0.00962438865086499 0.0352034287339324 0.000174576348464699"
        rpy="0 0 0" />
      <mass
        value="0.437130215853825" />
      <inertia
        ixx="0.000866914153248162"
        ixy="0.000148761646913658"
        ixz="-7.42553547352418E-07"
        iyy="0.000267753002587659"
        iyz="2.68058265485487E-06"
        izz="0.000952324298928136" />
    </inertial>
    <visual>
      <origin
        xyz="0 0 0"
        rpy="0 0 0" />
      <geometry>
        <mesh
          filename="package://franka_description/robots/meshes_gen/Link4.dae" />
      </geometry>
      <material
        name="">
        <color
          rgba="1 1 1 1" />
      </material>
    </visual>
    <collision>
      <origin
        xyz="0 0 0"
        rpy="0 0 0" />
      <geometry>
        <mesh
          filename="package://franka_description/robots/meshes_gen/Link4.STL" />
      </geometry>
    </collision>
  </link>
  <joint
    name="panda_joint4"
    type="revolute">
    <origin
      xyz="0.04 0 0"
      rpy="1.5708 0 0" />
    <parent
      link="panda_link3" />
    <child
      link="panda_link4" />
    <axis
      xyz="0 0 1" />
    <limit
      lower="-2.8792"
      upper="0.9597"
      effort="25"
      velocity="3.141" />
  </joint>
  <link
    name="panda_link5">
    <inertial>
      <origin
        xyz="-4.77956518807332E-07 -3.84737693792594E-05 -0.066955487820054"
        rpy="0 0 0" />
      <mass
        value="0.424276753764529" />
      <inertia
        ixx="0.0011244489011316"
        ixy="7.5662322019411E-09"
        ixz="-1.71276249932628E-08"
        iyy="0.00103382374928123"
        iyz="8.24694417478756E-07"
        izz="0.000274640088277484" />
    </inertial>
    <visual>
      <origin
        xyz="0 0 0"
        rpy="0 0 0" />
      <geometry>
        <mesh
          filename="package://franka_description/robots/meshes_gen/Link5.dae" />
      </geometry>
      <material
        name="">
        <color
          rgba="1 1 1 1" />
      </material>
    </visual>
    <collision>
      <origin
        xyz="0 0 0"
        rpy="0 0 0" />
      <geometry>
        <mesh
          filename="package://franka_description/robots/meshes_gen/Link5.STL" />
      </geometry>
    </collision>
  </link>
  <joint
    name="panda_joint5"
    type="revolute">
    <origin
      xyz="-0.019 0.2525 0"
      rpy="-1.5708 0 0" />
    <parent
      link="panda_link4" />
    <child
      link="panda_link5" />
    <axis
      xyz="0 0 1" />
    <limit
      lower="-3.0014"
      upper="3.0014"
      effort="5"
      velocity="3.926" />
  </joint>
  <link
    name="panda_link6">
    <inertial>
      <origin
        xyz="0.00184221861298974 0.0379763265035087 -9.21090904324278E-05"
        rpy="0 0 0" />
      <mass
        value="0.302793039332829" />
      <inertia
        ixx="0.00014011480503376"
        ixy="-3.00204828273403E-06"
        ixz="-4.58155498966787E-10"
        iyy="0.000132631402640971"
        iyz="7.01344540253995E-10"
        izz="0.000155721320872423" />
    </inertial>
    <visual>
      <origin
        xyz="0 0 0"
        rpy="0 0 0" />
      <geometry>
        <mesh
          filename="package://franka_description/robots/meshes_gen/Link6.dae" />
      </geometry>
      <material
        name="">
        <color
          rgba="1 1 1 1" />
      </material>
    </visual>
    <collision>
      <origin
        xyz="0 0 0"
        rpy="0 0 0" />
      <geometry>
        <mesh
          filename="package://franka_description/robots/meshes_gen/Link6.STL" />
      </geometry>
    </collision>
  </link>
  <joint
    name="panda_joint6"
    type="revolute">
    <origin
      xyz="0 0 0"
      rpy="1.5708 0 0" />
    <parent
      link="panda_link5" />
    <child
      link="panda_link6" />
    <axis
      xyz="0 0 1" />
    <limit
      lower="-1.707"
      upper="1.783"
      effort="5"
      velocity="3.926" />
  </joint>
  <link
    name="panda_link7">
    <inertial>
      <origin
        xyz="0.000199884675729955 -4.25081843764018E-08 -0.0292498694019246"
        rpy="0 0 0" />
      <mass
        value="0.176612671882913" />
      <inertia
        ixx="6.24281233883421E-05"
        ixy="2.55814128580721E-10"
        ixz="-3.1014379202721E-12"
        iyy="6.24291486534025E-05"
        iyz="1.37181281239386E-11"
        izz="8.48642555354654E-05" />
    </inertial>
    <visual>
      <origin
        xyz="0 0 0"
        rpy="0 0 0" />
      <geometry>
        <mesh
          filename="package://franka_description/robots/meshes_gen/Link7.dae" />
      </geometry>
      <material
        name="">
        <color
          rgba="1 1 1 1" />
      </material>
    </visual>
    <collision>
      <origin
        xyz="0 0 0"
        rpy="0 0 0" />
      <geometry>
        <mesh
          filename="package://franka_description/robots/meshes_gen/Link7.STL" />
      </geometry>
    </collision>
  </link>
  <joint
    name="panda_join7"
    type="revolute">
    <origin
      xyz="0.0905 0.067 0"
      rpy="1.5708 0 1.5708" />
    <parent
      link="panda_link6" />
    <child
      link="panda_link7" />
    <axis
      xyz="0 0 1" />
    <limit
      lower="-3.0014"
      upper="3.0014"
      effort="5"
      velocity="3.926" />
  </joint>
  <!-- <link name="panda_link8"/>
  <joint name="panda_joint8" type="fixed">
    <origin rpy="0 0 0" xyz="0 0 0.107"/>
    <parent link="panda_link7"/>
    <child link="panda_link8"/>
  </joint> -->
  <!-- sub-link defining detailed meshes for collision with environment -->
  <!-- Panda hand -->
  <joint name="panda_hand_joint" type="fixed">
    <parent link="panda_link7"/>
    <child link="panda_hand"/>
    <origin rpy="0 0 0" xyz="0 0 0"/>
  </joint>

  <link
    name="panda_hand">
    <inertial>
      <origin
        xyz="0.000590732710131745 -0.00212482055829597 0.0390711121564613"
        rpy="0 0 0" />
      <mass
        value="0.410076712822003" />
      <inertia
        ixx="0.000490743093860451"
        ixy="8.88694180287399E-06"
        ixz="-4.40788336869861E-07"
        iyy="0.000921185312665057"
        iyz="3.47120316959879E-05"
        izz="0.00085013675383108" />
    </inertial>
    <visual>
      <origin
        xyz="0 0 0"
        rpy="0 0 0" />
      <geometry>
        <mesh
          filename="package://franka_description/robots/Gripper/meshes/panda_hand.dae" />
      </geometry>
      <material
        name="">
        <color
          rgba="0.749019607843137 0.749019607843137 0.749019607843137 1" />
      </material>
    </visual>
    <collision>
      <origin
        xyz="0 0 0"
        rpy="0 0 0" />
      <geometry>
        <mesh
          filename="package://franka_description/robots/Gripper/meshes/panda_hand.stl" />
      </geometry>
    </collision>
  </link>
  <link
    name="panda_leftfinger">
    <inertial>
      <origin
        xyz="-0.14078 0.018679 0.052776"
        rpy="0 0 0" />
      <mass
        value="0.11401" />
      <inertia
        ixx="7.9791E-05"
        ixy="-1.4328E-07"
        ixz="-6.9009E-06"
        iyy="9.604E-05"
        iyz="1.6264E-08"
        izz="3.962E-05" />
    </inertial>
    <visual>
      <origin
        xyz="0 0 0"
        rpy="0 0 0" />
      <geometry>
        <mesh
          filename="package://franka_description/robots/Gripper/meshes/Left_Gripper.dae" />
      </geometry>
      <material
        name="">
        <color
          rgba="0.79216 0.81961 0.93333 1" />
      </material>
    </visual>
    <!-- block0 -->
    <collision>
      <origin
        xyz="-0.145 0.022 0.0386"
        rpy="0 0 0" />
      <geometry>
        <box size="3.03e-2 2.58e-2 4.14e-2"/>
      </geometry>
    </collision>
    <!-- block1 -->
    <collision>
      <origin
        xyz="-0.145 0.022 0.08"
        rpy="0 0 0" />
      <geometry>
        <box size="3.03e-2 2.58e-2 4.14e-2"/>
      </geometry>
    </collision>
    <!-- block2 -->
    <collision>
      <origin
        xyz="-0.1399 0.022 0.109"
        rpy="0 0 0" />
      <geometry>
        <box size="2.26e-2 2.58e-2 2.09e-2"/>
      </geometry>
    </collision>
    <!-- block3 -->
    <collision>
      <origin
        xyz="-0.1356 0.022 0.125"
        rpy="0 0 0" />
      <geometry>
        <box size="1.43e-2 2.58e-2 1.60e-2"/>
      </geometry>
    </collision>
    <!-- block4 -->
    <collision>
      <origin
        xyz="-0.1314 0.022 0.142"
        rpy="0 0 0" />
      <geometry>
        <box size="4.66e-3 2.58e-2 1.70e-2"/>
      </geometry>
    </collision>
  </link>
  <joint
    name="LG"
    type="prismatic">
    <origin
      xyz="0.125 -0.02241 0.0801"
      rpy="0 0 0" />
    <parent
      link="panda_hand" />
    <child
      link="panda_leftfinger" />
    <axis
      xyz="-1 0 0" />
    <limit
      lower="0"
      upper="0.055"
      effort="10"
      velocity="0.1" />
  </joint>
  <link
    name="panda_rightfinger">
    <inertial>
      <origin
        xyz="-0.14059 0.0092217 0.053953"
        rpy="0 0 0" />
      <mass
        value="0.11017" />
      <inertia
        ixx="7.7997E-05"
        ixy="-1.4178E-07"
        ixz="-6.9009E-06"
        iyy="9.5588E-05"
        iyz="9.38E-09"
        izz="3.7415E-05" />
    </inertial>
    <visual>
      <origin
        xyz="0 0 0"
        rpy="0 0 0" />
      <geometry>
        <mesh
          filename="package://franka_description/robots/Gripper/meshes/Right_Gripper.dae" />
      </geometry>
      <material
        name="">
        <color
          rgba="0.79216 0.81961 0.93333 1" />
      </material>
    </visual>
    <!-- block0 -->
    <collision>
      <origin
        xyz="-0.145 0.012 0.0386"
        rpy="0 0 0" />
      <geometry>
        <box size="3.03e-2 2.58e-2 4.14e-2"/>
      </geometry>
    </collision>
    <!-- block1 -->
    <collision>
      <origin
        xyz="-0.145 0.012 0.08"
        rpy="0 0 0" />
      <geometry>
        <box size="3.03e-2 2.58e-2 4.14e-2"/>
      </geometry>
    </collision>
    <!-- block2 -->
    <collision>
      <origin
        xyz="-0.1399 0.012 0.109"
        rpy="0 0 0" />
      <geometry>
        <box size="2.26e-2 2.58e-2 2.09e-2"/>
      </geometry>
    </collision>
    <!-- block3 -->
    <collision>
      <origin
        xyz="-0.1356 0.012 0.125"
        rpy="0 0 0" />
      <geometry>
        <box size="1.43e-2 2.58e-2 1.60e-2"/>
      </geometry>
    </collision>
    <!-- block4 -->
    <collision>
      <origin
        xyz="-0.1314 0.012 0.142"
        rpy="0 0 0" />
      <geometry>
        <box size="4.66e-3 2.58e-2 1.70e-2"/>
      </geometry>
    </collision>
  </link>
  <joint
    name="RG"
    type="prismatic">
    <origin
      xyz="-0.125 0.01159 0.0801"
      rpy="0 0 -3.1416" />
    <parent
      link="panda_hand" />
    <child
      link="panda_rightfinger" />
    <axis
      xyz="-1 0 0" />
    <limit
      lower="0"
      upper="0.055"
      effort="10"
      velocity="0.1" />
  </joint>



  <joint name="k_ee" type="fixed">
    <parent link="panda_hand"/>
    <child link="k_ee_link"/>
    <origin rpy="0 0 0" xyz="0 0 0.103399"/>
  </joint>
  <link name="k_ee_link">
  </link>
</robot>
